Workbook

Sheet Bewertung
A1: Bild | B1: Inhaltliche Genauigkeit | C1: Halluzinationen | D1: Detailtiefe | E1: Robustheit | F1: Konsistenz | G1: Kommentar / Kosten später | H1: Summe Kernkriterien | I1: Ø Kernkriterien | J1: Summe inkl. Konsistenz | K1: Ø inkl. Konsistenz
A2: 1 | B2: 4 | C2: 4 | D2: 5 | E2: 5 | H2: =SUM(B2:E2) -> 18 | I2: =AVERAGE(B2:E2) -> 4.5 | J2: =SUM(B2:F2) -> 18 | K2: =AVERAGE(B2:F2) -> 4.5
A3: 2 | B3: 4 | C3: 5 | D3: 3 | E3: 5 | H3: =SUM(B3:E3) -> 17 | I3: =AVERAGE(B3:E3) -> 4.25 | J3: =SUM(B3:F3) -> 17 | K3: =AVERAGE(B3:F3) -> 4.25
A4: 3 | B4: 4 | C4: 5 | D4: 5 | E4: 5 | H4: =SUM(B4:E4) -> 19 | I4: =AVERAGE(B4:E4) -> 4.75 | J4: =SUM(B4:F4) -> 19 | K4: =AVERAGE(B4:F4) -> 4.75
A5: 4 | B5: 3 | C5: 3 | D5: 5 | E5: 5 | H5: =SUM(B5:E5) -> 16 | I5: =AVERAGE(B5:E5) -> 4 | J5: =SUM(B5:F5) -> 16 | K5: =AVERAGE(B5:F5) -> 4
A6: 5 | B6: 4 | C6: 5 | D6: 4 | E6: 5 | H6: =SUM(B6:E6) -> 18 | I6: =AVERAGE(B6:E6) -> 4.5 | J6: =SUM(B6:F6) -> 18 | K6: =AVERAGE(B6:F6) -> 4.5
A7: 6 | B7: 3 | C7: 4 | D7: 5 | E7: 4 | F7: 3 | H7: =SUM(B7:E7) -> 16 | I7: =AVERAGE(B7:E7) -> 4 | J7: =SUM(B7:F7) -> 19 | K7: =AVERAGE(B7:F7) -> 3.8
A8: 7 | B8: 4 | C8: 3 | D8: 4 | E8: 4 | F8: 3 | H8: =SUM(B8:E8) -> 15 | I8: =AVERAGE(B8:E8) -> 3.75 | J8: =SUM(B8:F8) -> 18 | K8: =AVERAGE(B8:F8) -> 3.6
A9: 8 | B9: 4 | C9: 5 | D9: 5 | E9: 5 | H9: =SUM(B9:E9) -> 19 | I9: =AVERAGE(B9:E9) -> 4.75 | J9: =SUM(B9:F9) -> 19 | K9: =AVERAGE(B9:F9) -> 4.75
A10: 9 | B10: 3 | C10: 4 | D10: 5 | E10: 5 | H10: =SUM(B10:E10) -> 17 | I10: =AVERAGE(B10:E10) -> 4.25 | J10: =SUM(B10:F10) -> 17 | K10: =AVERAGE(B10:F10) -> 4.25
A11: 10 | B11: 4 | C11: 5 | D11: 4 | E11: 4 | H11: =SUM(B11:E11) -> 17 | I11: =AVERAGE(B11:E11) -> 4.25 | J11: =SUM(B11:F11) -> 17 | K11: =AVERAGE(B11:F11) -> 4.25
A12: 11 | B12: 3 | C12: 4 | D12: 5 | E12: 5 | H12: =SUM(B12:E12) -> 17 | I12: =AVERAGE(B12:E12) -> 4.25 | J12: =SUM(B12:F12) -> 17 | K12: =AVERAGE(B12:F12) -> 4.25
A13: 12 | B13: 4 | C13: 5 | D13: 4 | E13: 5 | H13: =SUM(B13:E13) -> 18 | I13: =AVERAGE(B13:E13) -> 4.5 | J13: =SUM(B13:F13) -> 18 | K13: =AVERAGE(B13:F13) -> 4.5
A14: 13 | B14: 4 | C14: 5 | D14: 5 | E14: 5 | F14: 4 | H14: =SUM(B14:E14) -> 19 | I14: =AVERAGE(B14:E14) -> 4.75 | J14: =SUM(B14:F14) -> 23 | K14: =AVERAGE(B14:F14) -> 4.6
A15: 14 | B15: 5 | C15: 5 | D15: 5 | E15: 5 | F15: 4 | H15: =SUM(B15:E15) -> 20 | I15: =AVERAGE(B15:E15) -> 5 | J15: =SUM(B15:F15) -> 24 | K15: =AVERAGE(B15:F15) -> 4.8
A16: 15 | B16: 1 | C16: 4 | D16: 3 | E16: 5 | H16: =SUM(B16:E16) -> 13 | I16: =AVERAGE(B16:E16) -> 3.25 | J16: =SUM(B16:F16) -> 13 | K16: =AVERAGE(B16:F16) -> 3.25
A17: 16 | B17: 3 | C17: 5 | D17: 4 | E17: 5 | H17: =SUM(B17:E17) -> 17 | I17: =AVERAGE(B17:E17) -> 4.25 | J17: =SUM(B17:F17) -> 17 | K17: =AVERAGE(B17:F17) -> 4.25
A18: 17 | B18: 3 | C18: 4 | D18: 4 | E18: 5 | H18: =SUM(B18:E18) -> 16 | I18: =AVERAGE(B18:E18) -> 4 | J18: =SUM(B18:F18) -> 16 | K18: =AVERAGE(B18:F18) -> 4
A19: 18 | B19: 3 | C19: 5 | D19: 4 | E19: 5 | H19: =SUM(B19:E19) -> 17 | I19: =AVERAGE(B19:E19) -> 4.25 | J19: =SUM(B19:F19) -> 17 | K19: =AVERAGE(B19:F19) -> 4.25
A20: 19 | B20: 2 | C20: 5 | D20: 4 | E20: 5 | H20: =SUM(B20:E20) -> 16 | I20: =AVERAGE(B20:E20) -> 4 | J20: =SUM(B20:F20) -> 16 | K20: =AVERAGE(B20:F20) -> 4
A21: 20 | B21: 5 | C21: 5 | D21: 4 | E21: 5 | F21: 3 | H21: =SUM(B21:E21) -> 19 | I21: =AVERAGE(B21:E21) -> 4.75 | J21: =SUM(B21:F21) -> 22 | K21: =AVERAGE(B21:F21) -> 4.4
A22: 21 | B22: 5 | C22: 5 | D22: 5 | E22: 5 | F22: 3 | H22: =SUM(B22:E22) -> 20 | I22: =AVERAGE(B22:E22) -> 5 | J22: =SUM(B22:F22) -> 23 | K22: =AVERAGE(B22:F22) -> 4.6
A23: 22 | B23: 4 | C23: 5 | D23: 5 | E23: 5 | H23: =SUM(B23:E23) -> 19 | I23: =AVERAGE(B23:E23) -> 4.75 | J23: =SUM(B23:F23) -> 19 | K23: =AVERAGE(B23:F23) -> 4.75
A24: 23 | B24: 3 | C24: 5 | D24: 3 | E24: 5 | H24: =SUM(B24:E24) -> 16 | I24: =AVERAGE(B24:E24) -> 4 | J24: =SUM(B24:F24) -> 16 | K24: =AVERAGE(B24:F24) -> 4
A25: 24 | B25: 4 | C25: 5 | D25: 5 | E25: 5 | H25: =SUM(B25:E25) -> 19 | I25: =AVERAGE(B25:E25) -> 4.75 | J25: =SUM(B25:F25) -> 19 | K25: =AVERAGE(B25:F25) -> 4.75
A26: 25 | B26: 4 | C26: 3 | D26: 5 | E26: 5 | H26: =SUM(B26:E26) -> 17 | I26: =AVERAGE(B26:E26) -> 4.25 | J26: =SUM(B26:F26) -> 17 | K26: =AVERAGE(B26:F26) -> 4.25
A27: 26 | B27: 4 | C27: 4 | D27: 5 | E27: 5 | H27: =SUM(B27:E27) -> 18 | I27: =AVERAGE(B27:E27) -> 4.5 | J27: =SUM(B27:F27) -> 18 | K27: =AVERAGE(B27:F27) -> 4.5
A28: 27 | B28: 5 | C28: 5 | D28: 4 | E28: 5 | F28: 4 | H28: =SUM(B28:E28) -> 19 | I28: =AVERAGE(B28:E28) -> 4.75 | J28: =SUM(B28:F28) -> 23 | K28: =AVERAGE(B28:F28) -> 4.6
A29: 28 | B29: 5 | C29: 5 | D29: 4 | E29: 5 | F29: 4 | H29: =SUM(B29:E29) -> 19 | I29: =AVERAGE(B29:E29) -> 4.75 | J29: =SUM(B29:F29) -> 23 | K29: =AVERAGE(B29:F29) -> 4.6
A30: 29 | B30: 3 | C30: 5 | D30: 4 | E30: 5 | H30: =SUM(B30:E30) -> 17 | I30: =AVERAGE(B30:E30) -> 4.25 | J30: =SUM(B30:F30) -> 17 | K30: =AVERAGE(B30:F30) -> 4.25
A31: 30 | B31: 3 | C31: 5 | D31: 4 | E31: 5 | H31: =SUM(B31:E31) -> 17 | I31: =AVERAGE(B31:E31) -> 4.25 | J31: =SUM(B31:F31) -> 17 | K31: =AVERAGE(B31:F31) -> 4.25
A32: 31 | B32: 4 | C32: 5 | D32: 4 | E32: 5 | H32: =SUM(B32:E32) -> 18 | I32: =AVERAGE(B32:E32) -> 4.5 | J32: =SUM(B32:F32) -> 18 | K32: =AVERAGE(B32:F32) -> 4.5
A33: 32 | B33: 3 | C33: 4 | D33: 5 | E33: 5 | H33: =SUM(B33:E33) -> 17 | I33: =AVERAGE(B33:E33) -> 4.25 | J33: =SUM(B33:F33) -> 17 | K33: =AVERAGE(B33:F33) -> 4.25
A34: 33 | B34: 4 | C34: 4 | D34: 4 | E34: 5 | G34: gutes Beispiel für Noise Reaction | H34: =SUM(B34:E34) -> 17 | I34: =AVERAGE(B34:E34) -> 4.25 | J34: =SUM(B34:F34) -> 17 | K34: =AVERAGE(B34:F34) -> 4.25
A35: 34 | B35: 5 | C35: 5 | D35: 4 | E35: 4 | F35: 3 | G35: Regentropfen nicht erkannt | H35: =SUM(B35:E35) -> 18 | I35: =AVERAGE(B35:E35) -> 4.5 | J35: =SUM(B35:F35) -> 21 | K35: =AVERAGE(B35:F35) -> 4.2
A36: 35 | B36: 5 | C36: 5 | D36: 5 | E36: 5 | F36: 3 | G36: Regentropfen erkannt | H36: =SUM(B36:E36) -> 20 | I36: =AVERAGE(B36:E36) -> 5 | J36: =SUM(B36:F36) -> 23 | K36: =AVERAGE(B36:F36) -> 4.6
A37: 36 | B37: 4 | C37: 4 | D37: 5 | E37: 5 | H37: =SUM(B37:E37) -> 18 | I37: =AVERAGE(B37:E37) -> 4.5 | J37: =SUM(B37:F37) -> 18 | K37: =AVERAGE(B37:F37) -> 4.5
A38: 37 | B38: 4 | C38: 5 | D38: 4 | E38: 5 | H38: =SUM(B38:E38) -> 18 | I38: =AVERAGE(B38:E38) -> 4.5 | J38: =SUM(B38:F38) -> 18 | K38: =AVERAGE(B38:F38) -> 4.5
A39: 38 | B39: 4 | C39: 5 | D39: 4 | E39: 5 | H39: =SUM(B39:E39) -> 18 | I39: =AVERAGE(B39:E39) -> 4.5 | J39: =SUM(B39:F39) -> 18 | K39: =AVERAGE(B39:F39) -> 4.5
A40: 39 | B40: 4 | C40: 5 | D40: 5 | E40: 5 | H40: =SUM(B40:E40) -> 19 | I40: =AVERAGE(B40:E40) -> 4.75 | J40: =SUM(B40:F40) -> 19 | K40: =AVERAGE(B40:F40) -> 4.75
...

Sheet Dashboard
A1: Auswertung Bewertungsmatrix GPT‑4o
A3: Anzahl Bilder | B3: =COUNT(Bewertung!A2:A78) -> 77
A4: Ø Kernkriterien | B4: =AVERAGE(Bewertung!I2:I78) -> 4.2824675
A5: Ø inkl. Konsistenz | B5: =AVERAGE(Bewertung!K2:K78) -> 4.2038961
A6: Bewertete Konsistenz-Fälle | B6: =COUNT(Bewertung!F2:F78) -> 22
A8: Kriterium | B8: Summe | C8: Durchschnitt | D8: Anzahl | E8: Hinweis
A9: Inhaltliche Genauigkeit | B9: =SUM(Bewertung!B2:B78) -> 291 | C9: =AVERAGE(Bewertung!B2:B78) -> 3.7792208 | D9: =COUNT(Bewertung!B2:B78) -> 77
A10: Halluzinationen | B10: =SUM(Bewertung!C2:C78) -> 333 | C10: =AVERAGE(Bewertung!C2:C78) -> 4.3246753 | D10: =COUNT(Bewertung!C2:C78) -> 77 | E10: Hohe Werte = wenige/keine Halluzinationen
A11: Detailtiefe | B11: =SUM(Bewertung!D2:D78) -> 326 | C11: =AVERAGE(Bewertung!D2:D78) -> 4.2337662 | D11: =COUNT(Bewertung!D2:D78) -> 77
A12: Robustheit | B12: =SUM(Bewertung!E2:E78) -> 369 | C12: =AVERAGE(Bewertung!E2:E78) -> 4.7922078 | D12: =COUNT(Bewertung!E2:E78) -> 77
A13: Konsistenz | B13: =SUM(Bewertung!F2:F78) -> 68 | C13: =AVERAGE(Bewertung!F2:F78) -> 3.0909091 | D13: =COUNT(Bewertung!F2:F78) -> 22 | E13: Nur dort sinnvoll, wo Vergleichsbilder bewertet wurden
A16: Top 10 nach Ø Kernkriterien
A17: Rang | B17: Bild | C17: Ø Kernkriterien | D17: Kommentar
A18: 1 | B18: 14 | C18: 5
A19: 2 | B19: 21 | C19: 5
A20: 3 | B20: 35 | C20: 5 | D20: Regentropfen erkannt
A21: 4 | B21: 52 | C21: 5 | D21: erstes mal „facing backward“
A22: 5 | B22: 3 | C22: 4.75
A23: 6 | B23: 8 | C23: 4.75
A24: 7 | B24: 13 | C24: 4.75
A25: 8 | B25: 20 | C25: 4.75
A26: 9 | B26: 22 | C26: 4.75
A27: 10 | B27: 24 | C27: 4.75
