Workbook

Sheet Bewertung
A1: BILDER | B1: INHALTL. GENAUIGKEIT | C1: HALLUZINATIONEN | D1: DETAILTIEFE | E1: ROBUSTHEIT | F1: KONSISTENZ | G1: Kommentar / Kosten später | H1: Summe Kernkriterien | I1: Ø Kernkriterien | J1: Summe inkl. Konsistenz | K1: Ø inkl. Konsistenz | L1: Rang Kern
A2: 1 | B2: 4 | C2: 3 | D2: 5 | E2: 5 | H2: =SUM(B2:E2) -> 17 | I2: =AVERAGE(B2:E2) -> 4.25 | J2: =SUM(B2:F2) -> 17 | K2: =AVERAGE(B2:F2) -> 4.25 | L2: =rank.eq(I2,$I$2:$I$78,0)+COUNTIF($I$2:I2,I2)-1 -> #NAME?
A3: 2 | B3: 3 | C3: 3 | D3: 5 | E3: 5 | H3: =SUM(B3:E3) -> 16 | I3: =AVERAGE(B3:E3) -> 4 | J3: =SUM(B3:F3) -> 16 | K3: =AVERAGE(B3:F3) -> 4 | L3: =rank.eq(I3,$I$2:$I$78,0)+COUNTIF($I$2:I3,I3)-1 -> #NAME?
A4: 3 | B4: 3 | C4: 2 | D4: 4 | E4: 5 | H4: =SUM(B4:E4) -> 14 | I4: =AVERAGE(B4:E4) -> 3.5 | J4: =SUM(B4:F4) -> 14 | K4: =AVERAGE(B4:F4) -> 3.5 | L4: =rank.eq(I4,$I$2:$I$78,0)+COUNTIF($I$2:I4,I4)-1 -> #NAME?
A5: 4 | B5: 3 | C5: 3 | D5: 4 | E5: 5 | H5: =SUM(B5:E5) -> 15 | I5: =AVERAGE(B5:E5) -> 3.75 | J5: =SUM(B5:F5) -> 15 | K5: =AVERAGE(B5:F5) -> 3.75 | L5: =rank.eq(I5,$I$2:$I$78,0)+COUNTIF($I$2:I5,I5)-1 -> #NAME?
A6: 5 | B6: 2 | C6: 4 | D6: 3 | E6: 5 | H6: =SUM(B6:E6) -> 14 | I6: =AVERAGE(B6:E6) -> 3.5 | J6: =SUM(B6:F6) -> 14 | K6: =AVERAGE(B6:F6) -> 3.5 | L6: =rank.eq(I6,$I$2:$I$78,0)+COUNTIF($I$2:I6,I6)-1 -> #NAME?
A7: 6 | B7: 3 | C7: 1 | D7: 3 | E7: 5 | F7: 2 | H7: =SUM(B7:E7) -> 12 | I7: =AVERAGE(B7:E7) -> 3 | J7: =SUM(B7:F7) -> 14 | K7: =AVERAGE(B7:F7) -> 2.8 | L7: =rank.eq(I7,$I$2:$I$78,0)+COUNTIF($I$2:I7,I7)-1 -> #NAME?
A8: 7 | B8: 2 | C8: 2 | D8: 3 | E8: 5 | F8: 2 | H8: =SUM(B8:E8) -> 12 | I8: =AVERAGE(B8:E8) -> 3 | J8: =SUM(B8:F8) -> 14 | K8: =AVERAGE(B8:F8) -> 2.8 | L8: =rank.eq(I8,$I$2:$I$78,0)+COUNTIF($I$2:I8,I8)-1 -> #NAME?
A9: 8 | B9: 3 | C9: 3 | D9: 2 | E9: 5 | G9: schafft es besser die location der kamera zu erkennen als 4o | H9: =SUM(B9:E9) -> 13 | I9: =AVERAGE(B9:E9) -> 3.25 | J9: =SUM(B9:F9) -> 13 | K9: =AVERAGE(B9:F9) -> 3.25 | L9: =rank.eq(I9,$I$2:$I$78,0)+COUNTIF($I$2:I9,I9)-1 -> #NAME?
A10: 9 | B10: 3 | C10: 4 | D10: 4 | E10: 5 | G10: begriffe für landwirtschaftliche geräte weniger gut | H10: =SUM(B10:E10) -> 16 | I10: =AVERAGE(B10:E10) -> 4 | J10: =SUM(B10:F10) -> 16 | K10: =AVERAGE(B10:F10) -> 4 | L10: =rank.eq(I10,$I$2:$I$78,0)+COUNTIF($I$2:I10,I10)-1 -> #NAME?
A11: 10 | B11: 3 | C11: 4 | D11: 2 | E11: 4 | H11: =SUM(B11:E11) -> 13 | I11: =AVERAGE(B11:E11) -> 3.25 | J11: =SUM(B11:F11) -> 13 | K11: =AVERAGE(B11:F11) -> 3.25 | L11: =rank.eq(I11,$I$2:$I$78,0)+COUNTIF($I$2:I11,I11)-1 -> #NAME?
A12: 11 | B12: 3 | C12: 2 | D12: 4 | E12: 5 | H12: =SUM(B12:E12) -> 14 | I12: =AVERAGE(B12:E12) -> 3.5 | J12: =SUM(B12:F12) -> 14 | K12: =AVERAGE(B12:F12) -> 3.5 | L12: =rank.eq(I12,$I$2:$I$78,0)+COUNTIF($I$2:I12,I12)-1 -> #NAME?
A13: 12 | B13: 4 | C13: 3 | D13: 4 | E13: 5 | H13: =SUM(B13:E13) -> 16 | I13: =AVERAGE(B13:E13) -> 4 | J13: =SUM(B13:F13) -> 16 | K13: =AVERAGE(B13:F13) -> 4 | L13: =rank.eq(I13,$I$2:$I$78,0)+COUNTIF($I$2:I13,I13)-1 -> #NAME?
A14: 13 | B14: 4 | C14: 4 | D14: 3 | E14: 5 | F14: 3 | H14: =SUM(B14:E14) -> 16 | I14: =AVERAGE(B14:E14) -> 4 | J14: =SUM(B14:F14) -> 19 | K14: =AVERAGE(B14:F14) -> 3.8 | L14: =rank.eq(I14,$I$2:$I$78,0)+COUNTIF($I$2:I14,I14)-1 -> #NAME?
A15: 14 | B15: 4 | C15: 3 | D15: 4 | E15: 5 | F15: 3 | H15: =SUM(B15:E15) -> 16 | I15: =AVERAGE(B15:E15) -> 4 | J15: =SUM(B15:F15) -> 19 | K15: =AVERAGE(B15:F15) -> 3.8 | L15: =rank.eq(I15,$I$2:$I$78,0)+COUNTIF($I$2:I15,I15)-1 -> #NAME?
A16: 15 | B16: 3 | C16: 2 | D16: 2 | E16: 5 | H16: =SUM(B16:E16) -> 12 | I16: =AVERAGE(B16:E16) -> 3 | J16: =SUM(B16:F16) -> 12 | K16: =AVERAGE(B16:F16) -> 3 | L16: =rank.eq(I16,$I$2:$I$78,0)+COUNTIF($I$2:I16,I16)-1 -> #NAME?
A17: 16 | B17: 3 | C17: 3 | D17: 4 | E17: 5 | H17: =SUM(B17:E17) -> 15 | I17: =AVERAGE(B17:E17) -> 3.75 | J17: =SUM(B17:F17) -> 15 | K17: =AVERAGE(B17:F17) -> 3.75 | L17: =rank.eq(I17,$I$2:$I$78,0)+COUNTIF($I$2:I17,I17)-1 -> #NAME?
A18: 17 | B18: 5 | C18: 5 | D18: 4 | E18: 5 | H18: =SUM(B18:E18) -> 19 | I18: =AVERAGE(B18:E18) -> 4.75 | J18: =SUM(B18:F18) -> 19 | K18: =AVERAGE(B18:F18) -> 4.75 | L18: =rank.eq(I18,$I$2:$I$78,0)+COUNTIF($I$2:I18,I18)-1 -> #NAME?
A19: 18 | B19: 3 | C19: 3 | D19: 3 | E19: 5 | H19: =SUM(B19:E19) -> 14 | I19: =AVERAGE(B19:E19) -> 3.5 | J19: =SUM(B19:F19) -> 14 | K19: =AVERAGE(B19:F19) -> 3.5 | L19: =rank.eq(I19,$I$2:$I$78,0)+COUNTIF($I$2:I19,I19)-1 -> #NAME?
A20: 19 | B20: 2 | C20: 4 | D20: 0 | E20: 4 | H20: =SUM(B20:E20) -> 10 | I20: =AVERAGE(B20:E20) -> 2.5 | J20: =SUM(B20:F20) -> 10 | K20: =AVERAGE(B20:F20) -> 2.5 | L20: =rank.eq(I20,$I$2:$I$78,0)+COUNTIF($I$2:I20,I20)-1 -> #NAME?
A21: 20 | B21: 3 | C21: 4 | D21: 4 | E21: 5 | F21: 4 | H21: =SUM(B21:E21) -> 16 | I21: =AVERAGE(B21:E21) -> 4 | J21: =SUM(B21:F21) -> 20 | K21: =AVERAGE(B21:F21) -> 4 | L21: =rank.eq(I21,$I$2:$I$78,0)+COUNTIF($I$2:I21,I21)-1 -> #NAME?
A22: 21 | B22: 5 | C22: 5 | D22: 4 | E22: 5 | F22: 4 | H22: =SUM(B22:E22) -> 19 | I22: =AVERAGE(B22:E22) -> 4.75 | J22: =SUM(B22:F22) -> 23 | K22: =AVERAGE(B22:F22) -> 4.6 | L22: =rank.eq(I22,$I$2:$I$78,0)+COUNTIF($I$2:I22,I22)-1 -> #NAME?
A23: 22 | B23: 2 | C23: 3 | D23: 3 | E23: 5 | H23: =SUM(B23:E23) -> 13 | I23: =AVERAGE(B23:E23) -> 3.25 | J23: =SUM(B23:F23) -> 13 | K23: =AVERAGE(B23:F23) -> 3.25 | L23: =rank.eq(I23,$I$2:$I$78,0)+COUNTIF($I$2:I23,I23)-1 -> #NAME?
A24: 23 | B24: 2 | C24: 4 | D24: 2 | E24: 4 | H24: =SUM(B24:E24) -> 12 | I24: =AVERAGE(B24:E24) -> 3 | J24: =SUM(B24:F24) -> 12 | K24: =AVERAGE(B24:F24) -> 3 | L24: =rank.eq(I24,$I$2:$I$78,0)+COUNTIF($I$2:I24,I24)-1 -> #NAME?
A25: 24 | B25: 2 | C25: 3 | D25: 5 | E25: 5 | H25: =SUM(B25:E25) -> 15 | I25: =AVERAGE(B25:E25) -> 3.75 | J25: =SUM(B25:F25) -> 15 | K25: =AVERAGE(B25:F25) -> 3.75 | L25: =rank.eq(I25,$I$2:$I$78,0)+COUNTIF($I$2:I25,I25)-1 -> #NAME?
A26: 25 | B26: 4 | C26: 4 | D26: 4 | E26: 5 | H26: =SUM(B26:E26) -> 17 | I26: =AVERAGE(B26:E26) -> 4.25 | J26: =SUM(B26:F26) -> 17 | K26: =AVERAGE(B26:F26) -> 4.25 | L26: =rank.eq(I26,$I$2:$I$78,0)+COUNTIF($I$2:I26,I26)-1 -> #NAME?
A27: 26 | B27: 4 | C27: 3 | D27: 5 | E27: 4 | H27: =SUM(B27:E27) -> 16 | I27: =AVERAGE(B27:E27) -> 4 | J27: =SUM(B27:F27) -> 16 | K27: =AVERAGE(B27:F27) -> 4 | L27: =rank.eq(I27,$I$2:$I$78,0)+COUNTIF($I$2:I27,I27)-1 -> #NAME?
A28: 27 | B28: 4 | C28: 5 | D28: 3 | E28: 5 | F28: 3 | H28: =SUM(B28:E28) -> 17 | I28: =AVERAGE(B28:E28) -> 4.25 | J28: =SUM(B28:F28) -> 20 | K28: =AVERAGE(B28:F28) -> 4 | L28: =rank.eq(I28,$I$2:$I$78,0)+COUNTIF($I$2:I28,I28)-1 -> #NAME?
A29: 28 | B29: 3 | C29: 5 | D29: 3 | E29: 5 | F29: 3 | H29: =SUM(B29:E29) -> 16 | I29: =AVERAGE(B29:E29) -> 4 | J29: =SUM(B29:F29) -> 19 | K29: =AVERAGE(B29:F29) -> 3.8 | L29: =rank.eq(I29,$I$2:$I$78,0)+COUNTIF($I$2:I29,I29)-1 -> #NAME?
A30: 29 | B30: 1 | C30: 5 | D30: 4 | E30: 5 | H30: =SUM(B30:E30) -> 15 | I30: =AVERAGE(B30:E30) -> 3.75 | J30: =SUM(B30:F30) -> 15 | K30: =AVERAGE(B30:F30) -> 3.75 | L30: =rank.eq(I30,$I$2:$I$78,0)+COUNTIF($I$2:I30,I30)-1 -> #NAME?
A31: 30 | B31: 4 | C31: 4 | D31: 3 | E31: 4 | H31: =SUM(B31:E31) -> 15 | I31: =AVERAGE(B31:E31) -> 3.75 | J31: =SUM(B31:F31) -> 15 | K31: =AVERAGE(B31:F31) -> 3.75 | L31: =rank.eq(I31,$I$2:$I$78,0)+COUNTIF($I$2:I31,I31)-1 -> #NAME?
A32: 31 | B32: 3 | C32: 3 | D32: 3 | E32: 5 | H32: =SUM(B32:E32) -> 14 | I32: =AVERAGE(B32:E32) -> 3.5 | J32: =SUM(B32:F32) -> 14 | K32: =AVERAGE(B32:F32) -> 3.5 | L32: =rank.eq(I32,$I$2:$I$78,0)+COUNTIF($I$2:I32,I32)-1 -> #NAME?
A33: 32 | B33: 3 | C33: 3 | D33: 5 | E33: 5 | H33: =SUM(B33:E33) -> 16 | I33: =AVERAGE(B33:E33) -> 4 | J33: =SUM(B33:F33) -> 16 | K33: =AVERAGE(B33:F33) -> 4 | L33: =rank.eq(I33,$I$2:$I$78,0)+COUNTIF($I$2:I33,I33)-1 -> #NAME?
A34: 33 | B34: 2 | C34: 2 | D34: 5 | E34: 4 | H34: =SUM(B34:E34) -> 13 | I34: =AVERAGE(B34:E34) -> 3.25 | J34: =SUM(B34:F34) -> 13 | K34: =AVERAGE(B34:F34) -> 3.25 | L34: =rank.eq(I34,$I$2:$I$78,0)+COUNTIF($I$2:I34,I34)-1 -> #NAME?
A35: 34 | B35: 5 | C35: 5 | D35: 3 | E35: 3 | F35: 2 | G35: regentropfen nicht erkannt | H35: =SUM(B35:E35) -> 16 | I35: =AVERAGE(B35:E35) -> 4 | J35: =SUM(B35:F35) -> 18 | K35: =AVERAGE(B35:F35) -> 3.6 | L35: =rank.eq(I35,$I$2:$I$78,0)+COUNTIF($I$2:I35,I35)-1 -> #NAME?
A36: 35 | B36: 5 | C36: 4 | D36: 3 | E36: 4 | F36: 2 | G36: hier regentropfen wieder erkannt | H36: =SUM(B36:E36) -> 16 | I36: =AVERAGE(B36:E36) -> 4 | J36: =SUM(B36:F36) -> 18 | K36: =AVERAGE(B36:F36) -> 3.6 | L36: =rank.eq(I36,$I$2:$I$78,0)+COUNTIF($I$2:I36,I36)-1 -> #NAME?
A37: 36 | B37: 2 | C37: 4 | D37: 4 | E37: 5 | G37: cultivator erkannt- glaube 4o konnte das nicht | H37: =SUM(B37:E37) -> 15 | I37: =AVERAGE(B37:E37) -> 3.75 | J37: =SUM(B37:F37) -> 15 | K37: =AVERAGE(B37:F37) -> 3.75 | L37: =rank.eq(I37,$I$2:$I$78,0)+COUNTIF($I$2:I37,I37)-1 -> #NAME?
A38: 37 | B38: 2 | C38: 4 | D38: 4 | E38: 5 | H38: =SUM(B38:E38) -> 15 | I38: =AVERAGE(B38:E38) -> 3.75 | J38: =SUM(B38:F38) -> 15 | K38: =AVERAGE(B38:F38) -> 3.75 | L38: =rank.eq(I38,$I$2:$I$78,0)+COUNTIF($I$2:I38,I38)-1 -> #NAME?
A39: 38 | B39: 3 | C39: 4 | D39: 4 | E39: 5 | H39: =SUM(B39:E39) -> 16 | I39: =AVERAGE(B39:E39) -> 4 | J39: =SUM(B39:F39) -> 16 | K39: =AVERAGE(B39:F39) -> 4 | L39: =rank.eq(I39,$I$2:$I$78,0)+COUNTIF($I$2:I39,I39)-1 -> #NAME?
A40: 39 | B40: 5 | C40: 4 | D40: 4 | E40: 5 | H40: =SUM(B40:E40) -> 18 | I40: =AVERAGE(B40:E40) -> 4.5 | J40: =SUM(B40:F40) -> 18 | K40: =AVERAGE(B40:F40) -> 4.5 | L40: =rank.eq(I40,$I$2:$I$78,0)+COUNTIF($I$2:I40,I40)-1 -> #NAME?
...

Sheet Dashboard
A1: Dashboard – Bewertung 4o-mini
A3: Kennzahl | B3: Wert
A4: Anzahl Bilder | B4: =COUNTA(Bewertung!$A$2:$A$78) -> 77
A5: Ø Kernkriterien | B5: =AVERAGE(Bewertung!$I$2:$I$78) -> 3.775974
A6: Ø inkl. Konsistenz | B6: =AVERAGE(Bewertung!$K$2:$K$78) -> 3.7324675
A7: Bewertete Konsistenzwerte | B7: =COUNT(Bewertung!$F$2:$F$78) -> 22
A9: Kriterium | B9: Anzahl | C9: Summe | D9: Durchschnitt
A10: Inhaltliche Genauigkeit | B10: =Bewertung!$B$82 -> 77 | C10: =Bewertung!$B$80 -> 253 | D10: =Bewertung!$B$81 -> 3.2857143
A11: Halluzinationen | B11: =Bewertung!$C$82 -> 77 | C11: =Bewertung!$C$80 -> 276 | D11: =Bewertung!$C$81 -> 3.5844156
A12: Detailtiefe | B12: =Bewertung!$D$82 -> 77 | C12: =Bewertung!$D$80 -> 265 | D12: =Bewertung!$D$81 -> 3.4415584
A13: Robustheit | B13: =Bewertung!$E$82 -> 77 | C13: =Bewertung!$E$80 -> 369 | D13: =Bewertung!$E$81 -> 4.7922078
A14: Konsistenz | B14: =Bewertung!$F$82 -> 22 | C14: =Bewertung!$F$80 -> 72 | D14: =Bewertung!$F$81 -> 3.2727273
A39: Top 10 Bilder nach Ø Kernkriterien
A40: Bild | B40: Ø Kernkriterien
A41: =INDEX(Bewertung!$A$2:$A$78,MATCH(ROW(A1),Bewertung!$L$2:$L$78,0)) -> #N/A | B41: =INDEX(Bewertung!$I$2:$I$78,MATCH(ROW(A1),Bewertung!$L$2:$L$78,0)) -> #N/A
A42: =INDEX(Bewertung!$A$2:$A$78,MATCH(ROW(A2),Bewertung!$L$2:$L$78,0)) -> #N/A | B42: =INDEX(Bewertung!$I$2:$I$78,MATCH(ROW(A2),Bewertung!$L$2:$L$78,0)) -> #N/A
A43: =INDEX(Bewertung!$A$2:$A$78,MATCH(ROW(A3),Bewertung!$L$2:$L$78,0)) -> #N/A | B43: =INDEX(Bewertung!$I$2:$I$78,MATCH(ROW(A3),Bewertung!$L$2:$L$78,0)) -> #N/A
A44: =INDEX(Bewertung!$A$2:$A$78,MATCH(ROW(A4),Bewertung!$L$2:$L$78,0)) -> #N/A | B44: =INDEX(Bewertung!$I$2:$I$78,MATCH(ROW(A4),Bewertung!$L$2:$L$78,0)) -> #N/A
A45: =INDEX(Bewertung!$A$2:$A$78,MATCH(ROW(A5),Bewertung!$L$2:$L$78,0)) -> #N/A | B45: =INDEX(Bewertung!$I$2:$I$78,MATCH(ROW(A5),Bewertung!$L$2:$L$78,0)) -> #N/A
A46: =INDEX(Bewertung!$A$2:$A$78,MATCH(ROW(A6),Bewertung!$L$2:$L$78,0)) -> #N/A | B46: =INDEX(Bewertung!$I$2:$I$78,MATCH(ROW(A6),Bewertung!$L$2:$L$78,0)) -> #N/A
A47: =INDEX(Bewertung!$A$2:$A$78,MATCH(ROW(A7),Bewertung!$L$2:$L$78,0)) -> #N/A | B47: =INDEX(Bewertung!$I$2:$I$78,MATCH(ROW(A7),Bewertung!$L$2:$L$78,0)) -> #N/A
A48: =INDEX(Bewertung!$A$2:$A$78,MATCH(ROW(A8),Bewertung!$L$2:$L$78,0)) -> #N/A | B48: =INDEX(Bewertung!$I$2:$I$78,MATCH(ROW(A8),Bewertung!$L$2:$L$78,0)) -> #N/A
A49: =INDEX(Bewertung!$A$2:$A$78,MATCH(ROW(A9),Bewertung!$L$2:$L$78,0)) -> #N/A | B49: =INDEX(Bewertung!$I$2:$I$78,MATCH(ROW(A9),Bewertung!$L$2:$L$78,0)) -> #N/A
A50: =INDEX(Bewertung!$A$2:$A$78,MATCH(ROW(A10),Bewertung!$L$2:$L$78,0)) -> #N/A | B50: =INDEX(Bewertung!$I$2:$I$78,MATCH(ROW(A10),Bewertung!$L$2:$L$78,0)) -> #N/A
A53: Bild | B53: Inhaltl. Genauigkeit | C53: Halluzinationen | D53: Detailtiefe | E53: Robustheit | F53: Ø Kern
A54: =Bewertung!A2 -> 1 | B54: =Bewertung!B2 -> 4 | C54: =Bewertung!C2 -> 3 | D54: =Bewertung!D2 -> 5 | E54: =Bewertung!E2 -> 5 | F54: =Bewertung!I2 -> 4.25
A55: =Bewertung!A3 -> 2 | B55: =Bewertung!B3 -> 3 | C55: =Bewertung!C3 -> 3 | D55: =Bewertung!D3 -> 5 | E55: =Bewertung!E3 -> 5 | F55: =Bewertung!I3 -> 4
A56: =Bewertung!A4 -> 3 | B56: =Bewertung!B4 -> 3 | C56: =Bewertung!C4 -> 2 | D56: =Bewertung!D4 -> 4 | E56: =Bewertung!E4 -> 5 | F56: =Bewertung!I4 -> 3.5
A57: =Bewertung!A5 -> 4 | B57: =Bewertung!B5 -> 3 | C57: =Bewertung!C5 -> 3 | D57: =Bewertung!D5 -> 4 | E57: =Bewertung!E5 -> 5 | F57: =Bewertung!I5 -> 3.75
A58: =Bewertung!A6 -> 5 | B58: =Bewertung!B6 -> 2 | C58: =Bewertung!C6 -> 4 | D58: =Bewertung!D6 -> 3 | E58: =Bewertung!E6 -> 5 | F58: =Bewertung!I6 -> 3.5
A59: =Bewertung!A7 -> 6 | B59: =Bewertung!B7 -> 3 | C59: =Bewertung!C7 -> 1 | D59: =Bewertung!D7 -> 3 | E59: =Bewertung!E7 -> 5 | F59: =Bewertung!I7 -> 3
A60: =Bewertung!A8 -> 7 | B60: =Bewertung!B8 -> 2 | C60: =Bewertung!C8 -> 2 | D60: =Bewertung!D8 -> 3 | E60: =Bewertung!E8 -> 5 | F60: =Bewertung!I8 -> 3
A61: =Bewertung!A9 -> 8 | B61: =Bewertung!B9 -> 3 | C61: =Bewertung!C9 -> 3 | D61: =Bewertung!D9 -> 2 | E61: =Bewertung!E9 -> 5 | F61: =Bewertung!I9 -> 3.25
A62: =Bewertung!A10 -> 9 | B62: =Bewertung!B10 -> 3 | C62: =Bewertung!C10 -> 4 | D62: =Bewertung!D10 -> 4 | E62: =Bewertung!E10 -> 5 | F62: =Bewertung!I10 -> 4
A63: =Bewertung!A11 -> 10 | B63: =Bewertung!B11 -> 3 | C63: =Bewertung!C11 -> 4 | D63: =Bewertung!D11 -> 2 | E63: =Bewertung!E11 -> 4 | F63: =Bewertung!I11 -> 3.25
A64: =Bewertung!A12 -> 11 | B64: =Bewertung!B12 -> 3 | C64: =Bewertung!C12 -> 2 | D64: =Bewertung!D12 -> 4 | E64: =Bewertung!E12 -> 5 | F64: =Bewertung!I12 -> 3.5
A65: =Bewertung!A13 -> 12 | B65: =Bewertung!B13 -> 4 | C65: =Bewertung!C13 -> 3 | D65: =Bewertung!D13 -> 4 | E65: =Bewertung!E13 -> 5 | F65: =Bewertung!I13 -> 4
... A130: =Bewertung!A78 -> 77 | B130: =Bewertung!B78 -> 4 | C130: =Bewertung!C78 -> 4 | D130: =Bewertung!D78 -> 1 | E130: =Bewertung!E78 -> 5 | F130: =Bewertung!I78 -> 3.5
